<robot name="nimbro">
  <material name="black">
    <color rgba="0.1 0.1 0.1 1" />
  </material>
  <!-- <link name="world"/> -->
  <link name="trunk_link">
    <inertial>
      <origin xyz="-0.016856 -0.00019822 0.019225" rpy="0 0 0" />
      <mass value="1.8051" />
      <inertia ixx="0.016444" ixy="1.4574E-05" ixz="0.00048254"
	       iyy="0.013972" iyz="5.0355E-06" izz="0.0064508" />
    </inertial>
    <visual>
      <origin xyz="0 0 0" rpy="0 0 0" />
      <geometry>
	<mesh filename="package://nimbro_op_model/mesh/nimbro_op_hull/trunk_link.STL" />
      </geometry>
      <material name="black" />
    </visual>
    <collision>
      <origin xyz="0 0 0" rpy="0 0 0" />
      <geometry>
	<mesh filename="package://nimbro_op_model/mesh/nimbro_op_hull/trunk_link.STL" />
      </geometry>
    </collision>
  </link>
  <link name="imu_link"/>
  <joint name="imu" type="fixed">
    <origin xyz="0 0 0" rpy="0 0 0" />
    <parent link="trunk_link" />
    <child link="imu_link" />
  </joint>
  <link name="right_hip_yaw_link">
    <inertial>
      <origin xyz="4.7878E-16 2.8449E-16 -0.013803" rpy="0 0 0" />
      <mass value="0.073374" />
      <inertia ixx="2.6774E-05" ixy="1.5536E-19" ixz="-9.0622E-19"
	       iyy="0.00011478" iyz="-2.2736E-19" izz="0.00010743" />
    </inertial>
    <visual>
      <origin xyz="0 0 0" rpy="0 0 0" />
      <geometry>
	<mesh filename="package://nimbro_op_model/mesh/nimbro_op_hull/right_hip_yaw_link.STL" />
      </geometry>
      <material name="black" />
    </visual>
    <collision>
      <origin xyz="0 0 0" rpy="0 0 0" />
      <geometry>
	<mesh filename="package://nimbro_op_model/mesh/nimbro_op_hull/right_hip_yaw_link.STL" />
      </geometry>
    </collision>
  </link>
  <joint name="right_hip_yaw" type="continuous">
    <origin xyz="-0.019 -0.055 -0.0936" rpy="0 0 0" />
    <parent link="trunk_link" />
    <child link="right_hip_yaw_link" />
    <axis xyz="0 0 1" />
    <limit lower="-1.5" upper="1.5" effort="30" velocity="15"/>
  </joint>

  <link name="right_hip_roll_link">
    <inertial>
      <origin xyz="0.010896 0.00023756 -0.014538" rpy="0 0 0" />
      <mass value="0.35903" />
      <inertia ixx="0.00015503" ixy="1.738E-06" ixz="8.5148E-06"
	       iyy="0.0003299" iyz="2.4403E-07" izz="0.0002782" />
    </inertial>
    <visual>
      <origin xyz="0 0 0" rpy="0 0 0" />
      <geometry>
	<mesh filename="package://nimbro_op_model/mesh/nimbro_op_hull/right_hip_roll_link.STL" />
      </geometry>
      <material name="black" />
    </visual>
    <collision>
      <origin xyz="0 0 0" rpy="0 0 0" />
      <geometry>
	<mesh filename="package://nimbro_op_model/mesh/nimbro_op_hull/right_hip_roll_link.STL" />
      </geometry>
    </collision>
  </link>
  <joint name="right_hip_roll" type="revolute">
    <origin xyz="-0.00721428464376577 0 -0.0438" rpy="0 0 0" />
    <parent link="right_hip_yaw_link" />
    <child link="right_hip_roll_link" />
    <axis xyz="1 0 0" />
    <limit lower="-1.5" upper="1.5" effort="30" velocity="15"/>
  </joint>

  
  <link name="right_thigh_link">
    <inertial>
      <origin xyz="0.0038549 0.00023828 -0.1495" rpy="0 0 0" />
      <mass value="0.38276" />
      <inertia ixx="0.0020951" ixy="1.8755E-07" ixz="-0.00017816"
	       iyy="0.0020043" iyz="-5.4867E-06" izz="0.00027919" />
    </inertial>
    <visual>
      <origin xyz="0 0 0" rpy="0 0 0" />
      <geometry>
	<mesh filename="package://nimbro_op_model/mesh/nimbro_op_hull/right_thigh_link.STL" />
      </geometry>
      <material name="black" />
    </visual>
    <collision>
      <origin xyz="0 0 0" rpy="0 0 0" />
      <geometry>
	<mesh filename="package://nimbro_op_model/mesh/nimbro_op_hull/right_thigh_link.STL" />
      </geometry>
    </collision>
  </link>
  <joint name="right_hip_pitch" type="continuous">
    <origin xyz="0.0303142846437658 0 0" rpy="0 0 0" />
    <parent link="right_hip_roll_link" />
    <child link="right_thigh_link" />
    <axis xyz="0 1 0" />
    <limit lower="-1.5" upper="1.5" effort="30" velocity="15"/>
  </joint>

  
  <link name="right_shank_link">
    <inertial>
      <origin xyz="-0.0033779 6.578E-10 -0.10469" rpy="0 0 0" />
      <mass value="0.20549" />
      <inertia ixx="0.0011378" ixy="-2.8771E-12" ixz="9.7123E-05"
	       iyy="0.0010393" iyz="-1.4479E-11" izz="0.00019656" />
    </inertial>
    <visual>
      <origin xyz="0 0 0" rpy="0 0 0" />
      <geometry>
	<mesh filename="package://nimbro_op_model/mesh/nimbro_op_hull/right_shank_link.STL" />
      </geometry>
      <material name="black" />
    </visual>
    <collision>
      <origin xyz="0 0 0" rpy="0 0 0" />
      <geometry>
	<mesh filename="package://nimbro_op_model/mesh/nimbro_op_hull/right_shank_link.STL" />
      </geometry>
    </collision>
  </link>
  <joint name="right_knee_pitch" type="revolute">
    <origin xyz="0 0 -0.22" rpy="0 0.05 0" />
    <parent link="right_thigh_link" />
    <child link="right_shank_link" />
    <axis xyz="0 1 0" />
    <limit lower="0.05" upper="2.5" effort="30" velocity="15"/>
  </joint>


  <link name="right_ankle_link">
    <inertial>
      <origin xyz="-0.019434 0.00024988 0.014536" rpy="0 0 0" />
      <mass value="0.35844" />
      <inertia ixx="0.00015501" ixy="1.7299E-06" ixz="-8.5156E-06"
	       iyy="0.00032958" iyz="-2.4435E-07" izz="0.00027786" />
    </inertial>
    <visual>
      <origin xyz="0 0 0" rpy="0 0 0" />
      <geometry>
	<mesh filename="package://nimbro_op_model/mesh/nimbro_op_hull/right_ankle_link.STL" />
      </geometry>
      <material name="black" />
    </visual>
    <collision>
      <origin xyz="0 0 0" rpy="0 0 0" />
      <geometry>
	<mesh filename="package://nimbro_op_model/mesh/nimbro_op_hull/right_ankle_link.STL" />
      </geometry>
    </collision>
  </link>
  <joint name="right_ankle_pitch" type="continuous">
    <origin xyz="0 0 -0.22" rpy="0 -0.04 0" />
    <parent link="right_shank_link" />
    <child link="right_ankle_link" />
    <axis xyz="0 1 0" />
    <limit lower="-1.5" upper="1.5" effort="30" velocity="15"/>
  </joint>


  <link name="right_foot_link">
    <inertial>
      <origin xyz="0.003669 -0.0081165 -0.030903" rpy="0 0 0" />
      <mass value="0.1488" />
      <inertia ixx="0.00018527" ixy="-1.1504E-05" ixz="-7.2667E-06"
	       iyy="0.00060485" iyz="5.8883E-06" izz="0.00075217" />
    </inertial>
    <visual>
      <origin xyz="0 0 0" rpy="0 0 0" />
      <geometry>
	<mesh filename="package://nimbro_op_model/mesh/nimbro_op_hull/right_foot_link.STL" />
      </geometry>
      <material name="black" />
    </visual>
    <collision>
      <origin xyz="0 0 0" rpy="0 0 0" />
      <geometry>
	<mesh filename="package://nimbro_op_model/mesh/nimbro_op_hull/right_foot_link.STL" />
      </geometry>
    </collision>
  </link>
  <joint name="right_ankle_roll" type="continuous">
    <origin xyz="0 0 0" rpy="0 0 0" />
    <parent link="right_ankle_link" />
    <child link="right_foot_link" />
    <axis xyz="1 0 0" />
    <limit lower="-1.5" upper="1.5" effort="30" velocity="15"/>
  </joint>


  <link name="right_foot_plane_link">
  </link>
  <joint name="right_foot_plane_joint" type="fixed">
    <origin xyz="0.0009 -0.011 -0.039"
	    rpy="0 0 0" />
    <parent link="right_foot_link" />
    <child link="right_foot_plane_link" />
  </joint>

  
  <link name="left_hip_yaw_link">
    <inertial>
      <origin xyz="4.996E-16 2.5674E-16 -0.013803" rpy="0 0 0" />
      <mass value="0.073374" />
      <inertia ixx="2.6774E-05" ixy="1.9727E-19" ixz="-8.7961E-19"
	       iyy="0.00011478" iyz="-2.3128E-19" izz="0.00010743" />
    </inertial>
    <visual>
      <origin xyz="0 0 0" rpy="0 0 0" />
      <geometry>
	<mesh filename="package://nimbro_op_model/mesh/nimbro_op_hull/left_hip_yaw_link.STL" />
      </geometry>
      <material name="black" />
    </visual>
    <collision>
      <origin xyz="0 0 0" rpy="0 0 0" />
      <geometry>
	<mesh filename="package://nimbro_op_model/mesh/nimbro_op_hull/left_hip_yaw_link.STL" />
      </geometry>
    </collision>
  </link>
  <joint name="left_hip_yaw" type="continuous">
    <origin xyz="-0.019 0.055 -0.0936" rpy="0 0 0" />
    <parent link="trunk_link" />
    <child link="left_hip_yaw_link" />
    <axis xyz="0 0 1" />
    <limit lower="-1.5" upper="1.5" effort="30" velocity="15"/>
  </joint>


  <link name="left_hip_roll_link">
    <inertial>
      <origin xyz="-0.019434 -0.0002499 -0.014536" rpy="0 0 0" />
      <mass value="0.35844" />
      <!-- TODO: the origin was shifted by -0.0012 and this was not updated -->
      <inertia ixx="0.00015501" ixy="-1.7299E-06" ixz="8.5156E-06"
	       iyy="0.00032958" iyz="-2.4435E-07" izz="0.00027786" />
    </inertial>
    <visual>
      <origin xyz="0 0 0" rpy="0 0 0" />
      <geometry>
	<mesh filename="package://nimbro_op_model/mesh/nimbro_op_hull/left_hip_roll_link.STL" />
      </geometry>
      <material name="black" />
    </visual>
    <collision>
      <origin xyz="0 0 0" rpy="0 0 0" />
      <geometry>
	<mesh filename="package://nimbro_op_model/mesh/nimbro_op_hull/left_hip_roll_link.STL" />
      </geometry>
    </collision>
  </link>
  <joint name="left_hip_roll" type="revolute">
    <origin xyz="0.0231 0.0 -0.0438" rpy="0 0 0" />
    <parent link="left_hip_yaw_link" />
    <child link="left_hip_roll_link" />
    <axis xyz="1 0 0" />
    <limit lower="-1.5" upper="1.5" effort="30" velocity="15"/>
  </joint>


  <link name="left_thigh_link">
    <inertial>
      <origin xyz="0.0038576 -0.0002383 -0.1495" rpy="0 0 0" />
      <mass value="0.38276" />
      
      <!-- TODO: the origin was shifted by -0.0012 and this was not updated -->
      <inertia ixx="0.0020952" ixy="-1.9541E-07" ixz="-0.00017822"
	       iyy="0.0020044" iyz="5.4912E-06" izz="0.00027919" />
    </inertial>
    <visual>
      <origin xyz="0 0 0" rpy="0 0 0" />
      <geometry>
	<mesh filename="package://nimbro_op_model/mesh/nimbro_op_hull/left_thigh_link.STL" />
      </geometry>
      <material name="black" />
    </visual>
    <collision>
      <origin xyz="0 0 0" rpy="0 0 0" />
      <geometry>
	<mesh filename="package://nimbro_op_model/mesh/nimbro_op_hull/left_thigh_link.STL" />
      </geometry>
    </collision>
  </link>
  <joint name="left_hip_pitch" type="revolute">
    <origin xyz="0 0 0" rpy="0 0 0" />
    <parent link="left_hip_roll_link" />
    <child link="left_thigh_link" />
    <axis xyz="0 1 0" />
    <limit lower="-1.5" upper="1.5" effort="30" velocity="15"/>
  </joint>


  <link name="left_shank_link">
    <inertial>
      <origin xyz="-0.0033779 -0.0012 -0.10469" rpy="0 0 0" />
      <mass value="0.20549" />
      <inertia ixx="0.0011378" ixy="-2.8771E-12" ixz="9.7123E-05"
	       iyy="0.0010393" iyz="-1.4479E-11" izz="0.00019656" />
    </inertial>
    <visual>
      <origin xyz="0 0 0" rpy="0 0 0" />
      <geometry>
	<mesh filename="package://nimbro_op_model/mesh/nimbro_op_hull/left_shank_link.STL" />
      </geometry>
      <material name="black" />
    </visual>
    <collision>
      <origin xyz="0 0 0" rpy="0 0 0" />
      <geometry>
	<mesh filename="package://nimbro_op_model/mesh/nimbro_op_hull/left_shank_link.STL" />
      </geometry>
    </collision>
  </link>
  <joint name="left_knee_pitch" type="revolute">
    <origin xyz="0 0 -0.22" rpy="0 0 0" />
    <parent link="left_thigh_link" />
    <child link="left_shank_link" />
    <axis xyz="0 1 0" />
    <limit lower="0" upper="2.5" effort="30" velocity="15"/>
  </joint>


  <link name="left_ankle_link">
    <inertial>
      <origin xyz="-0.019418 -0.0014376 0.014538" rpy="0 0 0" />
      <mass value="0.35903" />
      <inertia ixx="0.00015503" ixy="-1.738E-06" ixz="-8.5148E-06"
	       iyy="0.0003299" iyz="2.4403E-07" izz="0.0002782" />
    </inertial>
    <visual>
      <origin xyz="0 0 0" rpy="0 0 0" />
      <geometry>
	<mesh filename="package://nimbro_op_model/mesh/nimbro_op_hull/left_ankle_link.STL" />
      </geometry>
      <material name="black" />
    </visual>
    <collision>
      <origin xyz="0 0 0" rpy="0 0 0" />
      <geometry>
	<mesh filename="package://nimbro_op_model/mesh/nimbro_op_hull/left_ankle_link.STL" />
      </geometry>
    </collision>
  </link>
  <joint name="left_ankle_pitch" type="revolute">
    <origin xyz="0 0 -0.22" rpy="0 0 0" />
    <parent link="left_shank_link" />
    <child link="left_ankle_link" />
    <axis xyz="0 1 0" />
    <limit lower="-1.5" upper="1.5" effort="30" velocity="15"/>
  </joint>


  <link name="left_foot_link">
    <inertial>
      <origin xyz="0.0036084 0.0081189 -0.03091" rpy="0 0 0" />
      <mass value="0.1488" />
      <inertia ixx="0.0001853" ixy="1.1466E-05" ixz="-8.3793E-06"
	       iyy="0.00060485" iyz="-5.9046E-06" izz="0.00075213" />
    </inertial>
    <visual>
      <origin xyz="0 0 0" rpy="0 0 0" />
      <geometry>
	<mesh filename="package://nimbro_op_model/mesh/nimbro_op_hull/left_foot_link.STL" />
      </geometry>
      <material name="black" />
    </visual>
    <collision>
      <origin xyz="0 0 0" rpy="0 0 0" />
      <geometry>
	<mesh filename="package://nimbro_op_model/mesh/nimbro_op_hull/left_foot_link.STL" />
      </geometry>
      <surface>
        <friction>
          <ode>
            <mu>0.01</mu>
            <mu2>0.01</mu2>
          </ode>
        </friction>
      </surface>
    </collision>
  </link>
  <joint name="left_ankle_roll" type="revolute">
    <origin xyz="0 0 0" rpy="0 0 0" />
    <parent link="left_ankle_link" />
    <child link="left_foot_link" />
    <axis xyz="1 0 0" />
    <limit lower="-1.5" upper="1.5" effort="30" velocity="15"/>
  </joint>


  <link name="left_foot_plane_link">
  </link>
  <joint name="left_foot_plane_joint" type="fixed">
    <origin xyz="0.0009 0.011 -0.039"
	    rpy="0 0 0" />
    <parent link="left_foot_link" />
    <child link="left_foot_plane_link" />
  </joint>

  
  <link name="right_shoulder_pitch_link">
    <inertial>
      <origin xyz="1.7347E-17 -0.014621 1.6653E-16" rpy="0 0 0" />
      <mass value="0.025434" />
      <inertia ixx="6.7511E-06" ixy="1.5595E-20" ixz="-5.4198E-21"
	       iyy="1.2425E-05" iyz="-2.4006E-20" izz="1.4317E-05" />
    </inertial>
    <visual>
      <origin xyz="0 0 0" rpy="0 0 0" />
      <geometry>
	<mesh filename="package://nimbro_op_model/mesh/nimbro_op_hull/right_shoulder_pitch_link.STL" />
      </geometry>
      <material name="black" />
    </visual>
    <collision>
      <origin xyz="0 0 0" rpy="0 0 0" />
      <geometry>
	<mesh filename="package://nimbro_op_model/mesh/nimbro_op_hull/right_shoulder_pitch_link.STL" />
      </geometry>
    </collision>
  </link>
  <joint name="right_shoulder_pitch" type="continuous">
    <origin xyz="-0.0205 -0.0744999999999992 0.1075"
	    rpy="5.55111512312579E-15 6.12303176911189E-17 0" />
    <parent link="trunk_link" />
    <child link="right_shoulder_pitch_link" />
    <axis xyz="0 1 0" />
  </joint>


  <link name="right_upper_arm_link">
    <inertial>
      <origin xyz="0.0013671 0.00022653 -0.049517" rpy="0 0 0" />
      <mass value="0.2575" />
      <inertia ixx="0.00081539" ixy="1.1134E-07" ixz="-5.114E-05"
	       iyy="0.0007994" iyz="-2.4756E-06" izz="0.00012883" />
    </inertial>
    <visual>
      <origin xyz="0 0 0" rpy="0 0 0" />
      <geometry>
	<mesh filename="package://nimbro_op_model/mesh/nimbro_op_hull/right_shoulder_arm_link.STL" />
      </geometry>
      <material name="black" />
    </visual>
    <collision>
      <origin xyz="0 0 0" rpy="0 0 0" />
      <geometry>
	<mesh filename="package://nimbro_op_model/mesh/nimbro_op_hull/right_shoulder_arm_link.STL" />
      </geometry>
    </collision>
  </link>
  <joint name="right_shoulder_roll" type="continuous">
    <origin xyz="0 -0.0380000000000002 0"
	    rpy="-1.11022302462516E-14 3.08148791101957E-29 2.77555756156289E-15" />
    <parent link="right_shoulder_pitch_link" />
    <child link="right_upper_arm_link" />
    <axis xyz="1 0 0" />
  </joint>


  <link name="right_lower_arm_link">
    <inertial>
      <origin xyz="0.0018497 -0.00091671 -0.059095" rpy="0 0 0" />
      <mass value="0.23502" />
      <inertia ixx="0.0011613" ixy="-5.8221E-07" ixz="-7.4224E-05"
	       iyy="0.0011747" iyz="2.0082E-05" izz="0.00010273" />
    </inertial>
    <visual>
      <origin xyz="0 0 0" rpy="0 0 0" />
      <geometry>
	<mesh filename="package://nimbro_op_model/mesh/nimbro_op_hull/right_lower_arm_link.STL" />
      </geometry>
      <material name="black" />
    </visual>
    <collision>
      <origin xyz="0 0 0" rpy="0 0 0" />
      <geometry>
	<mesh filename="package://nimbro_op_model/mesh/nimbro_op_hull/right_lower_arm_link.STL" />
      </geometry>
    </collision>
  </link>
  <joint name="right_elbow_pitch" type="continuous">
    <origin xyz="0.0269999999999999 0 -0.17349723754798"
	    rpy="0.0402061998890168 0.00160692168991438 0.0100341647618143" />
    <parent link="right_upper_arm_link" />
    <child link="right_lower_arm_link" />
    <axis xyz="0.0100339834270393 0.99914218660165 -0.0401772339697495" />
  </joint>


  <link name="left_shoulder_pitch_link">
    <inertial>
      <origin xyz="-4.1633E-17 0.014621 -1.3878E-17" rpy="0 0 0" />
      <mass value="0.025434" />
      <inertia ixx="6.7511E-06" ixy="6.4644E-21" ixz="-3.365E-21"
	       iyy="1.2425E-05" iyz="-4.6109E-22" izz="1.4317E-05" />
    </inertial>
    <visual>
      <origin xyz="0 0 0" rpy="0 0 0" />
      <geometry>
	<mesh filename="package://nimbro_op_model/mesh/nimbro_op_hull/left_shoulder_pitch_link.STL" />
      </geometry>
      <material name="black" />
    </visual>
    <collision>
      <origin xyz="0 0 0" rpy="0 0 0" />
      <geometry>
	<mesh filename="package://nimbro_op_model/mesh/nimbro_op_hull/left_shoulder_pitch_link.STL" />
      </geometry>
    </collision>
  </link>
  <joint name="left_shoulder_pitch" type="continuous">
    <origin xyz="-0.0204999999999999 0.0745000000000003 0.1075"
	    rpy="-5.55111512312579E-15 6.12303176911189E-17 0" />
    <parent link="trunk_link" />
    <child link="left_shoulder_pitch_link" />
    <axis xyz="0 1 0" />
  </joint>

  
  <link name="left_upper_arm_link">
    <inertial>
      <origin xyz="0.0013671 0.00022653 -0.049517" rpy="0 0 0" />
      <mass value="0.2575" />
      <inertia ixx="0.00081539" ixy="1.1134E-07" ixz="-5.114E-05"
	       iyy="0.0007994" iyz="-2.4756E-06" izz="0.00012883" />
    </inertial>
    <visual>
      <origin xyz="0 0 0" rpy="0 0 0" />
      <geometry>
	<mesh filename="package://nimbro_op_model/mesh/nimbro_op_hull/left_upper_arm_link.STL" />
      </geometry>
      <material name="black" />
    </visual>
    <collision>
      <origin xyz="0 0 0" rpy="0 0 0" />
      <geometry>
	<mesh filename="package://nimbro_op_model/mesh/nimbro_op_hull/left_upper_arm_link.STL" />
      </geometry>
    </collision>
  </link>
  <joint name="left_shoulder_roll" type="continuous">
    <origin xyz="0 0.0380000000000002 0"
	    rpy="-2.3129646346366E-16 3.34362837567357E-31 1.44560289664736E-15" />
    <parent link="left_shoulder_pitch_link" />
    <child link="left_upper_arm_link" />
    <axis xyz="1 0 0" />
  </joint>


  <link name="left_lower_arm_link">
    <inertial>
      <origin xyz="0.001742 -6.4508E-05 -0.059095" rpy="0 0 0" />
      <mass value="0.23502" />
      <inertia ixx="0.0011616" ixy="-2.6303E-07" ixz="-7.2367E-05"
	       iyy="0.0011751" iyz="9.5624E-06" izz="0.00010214" />
    </inertial>
    <visual>
      <origin xyz="0 0 0" rpy="0 0 0" />
      <geometry>
	<mesh filename="package://nimbro_op_model/mesh/nimbro_op_hull/left_lower_arm_link.STL" />
      </geometry>
      <material name="black" />
    </visual>
    <collision>
      <origin xyz="0 0 0" rpy="0 0 0" />
      <geometry>
	<mesh filename="package://nimbro_op_model/mesh/nimbro_op_hull/left_lower_arm_link.STL" />
      </geometry>
    </collision>
  </link>
  <joint name="left_elbow_pitch" type="continuous">
    <origin xyz="0.0269999999999999 0 -0.17349723754798"
	    rpy="1.61907524424511E-15 -1.17961196366425E-15 4.62592926927126E-16" />
    <parent link="left_upper_arm_link" />
    <child link="left_lower_arm_link" />
    <axis xyz="0 1 0" />
  </joint>


  <link name="neck_link">
    <inertial>
      <origin xyz="2.1595E-05 0.00064781 0.033208" rpy="0 0 0" />
      <mass value="0.15587" />
      <inertia ixx="7.5209E-05" ixy="-1.8422E-06" ixz="-4.9817E-07"
	       iyy="6.2999E-05" iyz="-9.9088E-08" izz="3.826E-05" />
    </inertial>
    <visual>
      <origin xyz="0 0 0" rpy="0 0 0" />
      <geometry>
	<mesh filename="package://nimbro_op_model/mesh/nimbro_op_hull/neck_link.STL" />
      </geometry>
      <material name="black" />
    </visual>
    <collision>
      <origin xyz="0 0 0" rpy="0 0 0" />
      <geometry>
	<mesh filename="package://nimbro_op_model/mesh/nimbro_op_hull/neck_link.STL" />
      </geometry>
    </collision>
  </link>
  <joint name="neck_yaw" type="continuous">
    <origin xyz="-0.0284999999999998 0 0.1365"
	    rpy="-5.56000081322023E-15 6.05821451922983E-17 -0.145633370434016" />
    <parent link="trunk_link" />
    <child link="neck_link" />
    <axis xyz="0 0 1" />
  </joint>


  <link name="head_link">
    <inertial>
      <origin xyz="0.014358 0.0005519 0.069919" rpy="0 0 0" />
      <mass value="0.40746" />
      <inertia ixx="0.0014813" ixy="3.1631E-07" ixz="-4.1003E-05"
	       iyy="0.0016361" iyz="6.7483E-07" izz="0.0017353" />
    </inertial>
    <visual>
      <origin xyz="0 0 0" rpy="0 0 0" />
      <geometry>
	<mesh filename="package://nimbro_op_model/mesh/nimbro_op_hull/head_link.STL" />
      </geometry>
      <material name="">
	<color rgba="0.8 0.8 0.8 1" />
      </material>
    </visual>
    <collision>
      <origin xyz="0 0 0" rpy="0 0 0" />
      <geometry>
	<mesh filename="package://nimbro_op_model/mesh/nimbro_op_hull/head_link.STL" />
      </geometry>
    </collision>
  </link>
  <joint name="head_pitch" type="continuous">
    <origin xyz="0 0 0.0504999999999999"
	    rpy="-5.87630490298277E-17 -6.63424384579142E-15 0.145633370434016" />
    <parent link="neck_link" />
    <child link="head_link" />
    <axis xyz="0 1 0" />
  </joint>
  <link name="camera_optical" />
  <joint name="camera_joint" type="fixed">
    <!--origin xyz="0.0735836299363487 -0.0320999963345818 0.070595781755363"
	    rpy="-1.60399263964928 1.80630901483938E-16 -1.57079632679489" /-->
    <origin xyz="0.0735836299363487     0.0        0.063095782"
      rpy="      0                   0                  0     "      />
    <parent link="head_link" />
    <child link="camera_optical" />|
    <axis xyz="0 0 0" />
  </joint>

  <!-- Transmissions -->
  <transmission name="right_hip_yaw_transmission">
    <type>transmission_interface/SimpleTransmission</type>
    <joint name="right_hip_yaw" >
      <hardwareInterface>hardware_interface/EffortJointInterface</hardwareInterface>
    </joint>
    <actuator name="right_hip_yaw">
      <mechanicalReduction>1</mechanicalReduction>
    </actuator>
  </transmission>
  <transmission name="right_hip_roll_transmission">
    <type>transmission_interface/SimpleTransmission</type>
    <joint name="right_hip_roll" >
      <hardwareInterface>hardware_interface/EffortJointInterface</hardwareInterface>
    </joint>
    <actuator name="right_hip_roll">
      <mechanicalReduction>1</mechanicalReduction>
    </actuator>
  </transmission>
  <transmission name="right_hip_pitch_transmission">
    <type>transmission_interface/SimpleTransmission</type>
    <joint name="right_hip_pitch" >
      <hardwareInterface>hardware_interface/EffortJointInterface</hardwareInterface>
    </joint>
    <actuator name="right_hip_pitch">
      <mechanicalReduction>1</mechanicalReduction>
    </actuator>
  </transmission>
  <transmission name="right_knee_pitch_transmission">
    <type>transmission_interface/SimpleTransmission</type>
    <joint name="right_knee_pitch" >
      <hardwareInterface>hardware_interface/EffortJointInterface</hardwareInterface>
    </joint>
    <actuator name="right_knee_pitch">
      <mechanicalReduction>1</mechanicalReduction>
    </actuator>
  </transmission>
  <transmission name="right_ankle_pitch_transmission">
    <type>transmission_interface/SimpleTransmission</type>
    <joint name="right_ankle_pitch" >
      <hardwareInterface>hardware_interface/EffortJointInterface</hardwareInterface>
    </joint>
    <actuator name="right_ankle_pitch">
      <mechanicalReduction>1</mechanicalReduction>
    </actuator>
  </transmission>
  <transmission name="right_ankle_roll_transmission">
    <type>transmission_interface/SimpleTransmission</type>
    <joint name="right_ankle_roll" >
      <hardwareInterface>hardware_interface/EffortJointInterface</hardwareInterface>
    </joint>
    <actuator name="right_ankle_roll">
      <mechanicalReduction>1</mechanicalReduction>
    </actuator>
  </transmission>
  <transmission name="left_hip_yaw_transmission">
    <type>transmission_interface/SimpleTransmission</type>
    <joint name="left_hip_yaw" >
      <hardwareInterface>hardware_interface/EffortJointInterface</hardwareInterface>
    </joint>
    <actuator name="left_hip_yaw">
      <mechanicalReduction>1</mechanicalReduction>
    </actuator>
  </transmission>
  <transmission name="left_hip_roll_transmission">
    <type>transmission_interface/SimpleTransmission</type>
    <joint name="left_hip_roll" >
      <hardwareInterface>hardware_interface/EffortJointInterface</hardwareInterface>
    </joint>
    <actuator name="left_hip_roll">
      <mechanicalReduction>1</mechanicalReduction>
    </actuator>
  </transmission>
  <transmission name="left_hip_pitch_transmission">
    <type>transmission_interface/SimpleTransmission</type>
    <joint name="left_hip_pitch" >
      <hardwareInterface>hardware_interface/EffortJointInterface</hardwareInterface>
    </joint>
    <actuator name="left_hip_pitch">
      <mechanicalReduction>1</mechanicalReduction>
    </actuator>
  </transmission>
  <transmission name="left_knee_pitch_transmission">
    <type>transmission_interface/SimpleTransmission</type>
    <joint name="left_knee_pitch" >
      <hardwareInterface>hardware_interface/EffortJointInterface</hardwareInterface>
    </joint>
    <actuator name="left_knee_pitch">
      <mechanicalReduction>1</mechanicalReduction>
    </actuator>
  </transmission>
  <transmission name="left_ankle_pitch_transmission">
    <type>transmission_interface/SimpleTransmission</type>
    <joint name="left_ankle_pitch" >
      <hardwareInterface>hardware_interface/EffortJointInterface</hardwareInterface>
    </joint>
    <actuator name="left_ankle_pitch">
      <mechanicalReduction>1</mechanicalReduction>
    </actuator>
  </transmission>
  <transmission name="left_ankle_roll_transmission">
    <type>transmission_interface/SimpleTransmission</type>
    <joint name="left_ankle_roll" >
      <hardwareInterface>hardware_interface/EffortJointInterface</hardwareInterface>
    </joint>
    <actuator name="left_ankle_roll">
      <mechanicalReduction>1</mechanicalReduction>
    </actuator>
  </transmission>
  <transmission name="right_shoulder_pitch_transmission">
    <type>transmission_interface/SimpleTransmission</type>
    <joint name="right_shoulder_pitch" >
      <hardwareInterface>hardware_interface/EffortJointInterface</hardwareInterface>
    </joint>
    <actuator name="right_shoulder_pitch">
      <mechanicalReduction>1</mechanicalReduction>
    </actuator>
  </transmission>
  <transmission name="right_shoulder_roll_transmission">
    <type>transmission_interface/SimpleTransmission</type>
    <joint name="right_shoulder_roll" >
      <hardwareInterface>hardware_interface/EffortJointInterface</hardwareInterface>
    </joint>
    <actuator name="right_shoulder_roll">
      <mechanicalReduction>1</mechanicalReduction>
    </actuator>
  </transmission>
  <transmission name="right_elbow_pitch_transmission">
    <type>transmission_interface/SimpleTransmission</type>
    <joint name="right_elbow_pitch" >
      <hardwareInterface>hardware_interface/EffortJointInterface</hardwareInterface>
    </joint>
    <actuator name="right_elbow_pitch">
      <mechanicalReduction>1</mechanicalReduction>
    </actuator>
  </transmission>
  <transmission name="left_shoulder_pitch_transmission">
    <type>transmission_interface/SimpleTransmission</type>
    <joint name="left_shoulder_pitch" >
      <hardwareInterface>hardware_interface/EffortJointInterface</hardwareInterface>
    </joint>
    <actuator name="left_shoulder_pitch">
      <mechanicalReduction>1</mechanicalReduction>
    </actuator>
  </transmission>
  <transmission name="left_shoulder_roll_transmission">
    <type>transmission_interface/SimpleTransmission</type>
    <joint name="left_shoulder_roll" >
      <hardwareInterface>hardware_interface/EffortJointInterface</hardwareInterface>
    </joint>
    <actuator name="left_shoulder_roll">
      <mechanicalReduction>1</mechanicalReduction>
    </actuator>
  </transmission>
  <transmission name="left_elbow_pitch_transmission">
    <type>transmission_interface/SimpleTransmission</type>
    <joint name="left_elbow_pitch" >
      <hardwareInterface>hardware_interface/EffortJointInterface</hardwareInterface>
    </joint>
    <actuator name="left_elbow_pitch">
      <mechanicalReduction>1</mechanicalReduction>
    </actuator>
  </transmission>
  <transmission name="neck_yaw_transmission">
    <type>transmission_interface/SimpleTransmission</type>
    <joint name="neck_yaw" >
      <hardwareInterface>hardware_interface/EffortJointInterface</hardwareInterface>
    </joint>
    <actuator name="neck_yaw">
      <mechanicalReduction>1</mechanicalReduction>
    </actuator>
  </transmission>
  <transmission name="head_pitch_transmission">
    <type>transmission_interface/SimpleTransmission</type>
    <joint name="head_pitch" >
      <hardwareInterface>hardware_interface/EffortJointInterface</hardwareInterface>
    </joint>
    <actuator name="head_pitch">
      <mechanicalReduction>1</mechanicalReduction>
    </actuator>
  </transmission>
  
  
  <!-- Gazebo configuration -->
  
  <gazebo>
    <plugin name="gazebo_ros_control" filename="libgazebo_ros_control.so">
      <robotNamespace>/nimbro</robotNamespace>
    </plugin>
  </gazebo>

  <!-- Gazebo links -->
  <gazebo reference="trunk_link">
    <material>Gazebo/FlatBlack</material>
  </gazebo>
  <gazebo reference="left_hip_yaw_link">
    <material>Gazebo/FlatBlack</material>
  </gazebo>
  <gazebo reference="left_hip_roll_link">
    <material>Gazebo/Black</material>
  </gazebo>
  <gazebo reference="left_thigh_link">
    <material>Gazebo/FlatBlack</material>
  </gazebo>
  <gazebo reference="left_shank_link">
    <material>Gazebo/FlatBlack</material>
  </gazebo>
  <gazebo reference="left_ankle_link">
    <material>Gazebo/Black</material>
  </gazebo>
  <gazebo reference="left_foot_link">
    <material>Gazebo/FlatBlack</material>
    <kp>1000000.0</kp>
    <kd>100.0</kd>
    <mu1>1.0</mu1>
    <mu2>1.0</mu2>
    <fdir1>1 0 0</fdir1>
    <maxVel>1.0</maxVel>
    <minDepth>0.00</minDepth>
  </gazebo>
  <gazebo reference="left_shoulder_pitch_link">
    <material>Gazebo/Black</material>
  </gazebo>
  <gazebo reference="left_upper_arm_link">
    <material>Gazebo/FlatBlack</material>
  </gazebo>
  <gazebo reference="left_lower_arm_link">
    <material>Gazebo/FlatBlack</material>
  </gazebo>
  <gazebo reference="right_hip_yaw_link">
    <material>Gazebo/FlatBlack</material>
  </gazebo>
  <gazebo reference="right_hip_roll_link">
    <material>Gazebo/Black</material>
  </gazebo>
  <gazebo reference="right_thigh_link">
    <material>Gazebo/FlatBlack</material>
  </gazebo>
  <gazebo reference="right_shank_link">
    <material>Gazebo/FlatBlack</material>
  </gazebo>
  <gazebo reference="right_ankle_link">
    <material>Gazebo/Black</material>
  </gazebo>
  <gazebo reference="right_foot_link">
    <material>Gazebo/FlatBlack</material>
    <kp>1000000.0</kp>
    <kd>100.0</kd>
    <mu1>1.0</mu1>
    <mu2>1.0</mu2>
    <fdir1>1 0 0</fdir1>
    <maxVel>1.0</maxVel>
    <minDepth>0.00</minDepth>
  </gazebo>
  <gazebo reference="right_shoulder_pitch_link">
    <material>Gazebo/Black</material>
  </gazebo>
  <gazebo reference="right_upper_arm_link">
    <material>Gazebo/FlatBlack</material>
  </gazebo>
  <gazebo reference="right_lower_arm_link">
    <material>Gazebo/FlatBlack</material>
  </gazebo>
  <gazebo reference="neck_link">
    <material>Gazebo/Black</material>
  </gazebo>

  <!-- camera -->
  <gazebo reference="camera_optical">
    <sensor type="camera" name="camera1">
      <update_rate>30.0</update_rate>
      <camera name="head">
        <horizontal_fov>1.3962634</horizontal_fov>
        <image>
          <width>640</width>
          <height>480</height>
          <format>R8G8B8</format>
        </image>
        <clip>
          <near>0.02</near>
          <far>300</far>
        </clip>
        <noise>
          <type>gaussian</type>
          <!-- Noise is sampled independently per pixel on each frame.
               That pixel's noise value is added to each of its color
               channels, which at that point lie in the range [0,1]. -->
          <mean>0.0</mean>
          <stddev>0.007</stddev>
        </noise>
      </camera>
      <plugin name="camera_controller" filename="libgazebo_ros_camera.so">
        <alwaysOn>true</alwaysOn>
        <updateRate>0.0</updateRate>
        <cameraName>rrbot/camera1</cameraName>
		<imageTopicName>/hardware/camera/image</imageTopicName>
		<cameraInfoTopicName>/hardware/camera/camera_info</cameraInfoTopicName>
        <frameName>camera_link_optical</frameName>
        <!-- setting hackBaseline to anything but 0.0 will cause a misalignment
            between the gazebo sensor image and the frame it is supposed to
            be attached to -->
        <hackBaseline>0.0</hackBaseline>
        <distortionK1>0.0</distortionK1>
        <distortionK2>0.0</distortionK2>
        <distortionK3>0.0</distortionK3>
        <distortionT1>0.0</distortionT1>
        <distortionT2>0.0</distortionT2>
        <CxPrime>0</CxPrime>
        <Cx>0.0</Cx>
        <Cy>0.0</Cy>
        <focalLength>0.0</focalLength>
      </plugin>
    </sensor>
  </gazebo>
  <gazebo reference="imu_link">
    <gravity>true</gravity>
    <sensor name="imu_sensor" type="imu">
      <always_on>true</always_on>
      <update_rate>25</update_rate>
      <visualize>true</visualize>
      <topic>/imu/data_raw</topic>
      <plugin filename="libgazebo_ros_imu_sensor.so" name="imu_plugin">
        <topicName>imu/data_raw</topicName>
        <bodyName>imu_link</bodyName>
        <updateRateHZ>25.0</updateRateHZ>
        <gaussianNoise>0.0</gaussianNoise>
        <xyzOffset>0 0 0</xyzOffset>
        <rpyOffset>0 0 0</rpyOffset>
        <frameName>imu_link</frameName>
        <initialOrientationAsReference>false</initialOrientationAsReference>
      </plugin>
      <pose>0 0 0 0 0 0</pose>
    </sensor>
  </gazebo>
</robot>
